Workbook

Sheet Données
A1: Eau énergie | B1: 500 | D1: Tableau des salaires et charges | H1: Mdo assemblage
A2: Roues | B2: 20000 | D2: M. Dion | E2: 3000 | H2: Garçon | I2: 70
A3: Repose Pied | B3: 30000 | D3: M. Retron | E3: 12000 | H3: Fille | I3: 82
A4: Guidons | B4: 30000 | D4: M. Poliard | E4: 17000 | I4: 152
A5: Freins | B5: 10000 | D5: Mme Loudon | E5: 18000
A6: Auto-collants filles | B6: 1500
A7: Auto-collants garçons | B7: 2000
A8: Emballage garçon | B8: 2035
A9: Emballage fille | B9: 1485
A10: Garde-boue | B10: 8000
A11: Salaires et charges | B11: 50000
A12: Entretien | B12: 2400
A13: Publicité | B13: 5000
A14: Transport | B14: 1500
A15: Total | B15: 164420
A19: Achat trottinettes | D19: Production
A20: Garçon | B20: 1850 | D20: 1825
A21: Fille | B21: 1350 | D21: 1325
B22: 3200 | D22: 3150
A24: Éléments | B24: Qté
A25: Roue | B25: 6400
A26: Repose Pied | B26: 3200
A27: Guidons | B27: 3200
A28: Freins | B28: 3200
A29: Auto-collant filles | B29: 1350
A30: Auto-collant garçons | B30: 1850
A31: Emballages garçons | B31: 1850
A32: Emballages filles | B32: 1350
A33: Garde-boue | B33: 3200

Sheet Charges indirectes
C1: Centres Auxiliaires | E1: Centres Principaux
C2: Entretien | D2: Administration | E2: Achat | F2: Assemblage | G2: Commercialisation | H2: Total | J2: Lié au cout d'achat
A3: Eau énergie | B3: 500 | C3: 0.25 | D3: 0.05 | E3: 0.05 | F3: 0.6 | G3: 0.05 | H3: =SUM(C3:G3) -> 1 | J3: Lié au cout de production
A4: Salaires et charges | H4: =SUM(C4:G4) -> 0 | J4: Lié au cout hors production
A5: Dion | B5: 3000 | C5: 1 | H5: =SUM(C5:G5) -> 1
A6: Retron | B6: 12000 | F6: 1 | H6: =SUM(C6:G6) -> 1
A7: Poliard | B7: 17000 | E7: 1 | H7: =SUM(C7:G7) -> 1
A8: Loudon | B8: 18000 | D8: 0.2 | G8: 0.8 | H8: =SUM(C8:G8) -> 1
A9: Entretien | B9: 2400 | C9: 1 | H9: =SUM(C9:G9) -> 1
A10: Publicité | B10: 5000 | G10: 1 | H10: =SUM(C10:G10) -> 1
A11: Transport | B11: 1500 | G11: 1 | H11: =SUM(C11:G11) -> 1
B12: =SUM(B3:B11) -> 59400
C15: Centres Auxiliaires | E15: Centres Principaux
C16: Entretien | D16: Administration | E16: Achat | F16: Assemblage | G16: Commercialisation | H16: Total
A17: Eau énergie | B17: =Données!$B$1 -> 500 | C17: =$B17*C3 -> 125 | D17: =$B17*D3 -> 25 | E17: =$B17*E3 -> 25 | F17: =$B17*F3 -> 300 | G17: =$B17*G3 -> 25 | H17: =SUM(C17:G17) -> 500
A18: Salaires et charges | C18: =$B18*C4 -> 0 | D18: =$B18*D4 -> 0 | E18: =$B18*E4 -> 0 | F18: =$B18*F4 -> 0 | G18: =$B18*G4 -> 0 | H18: =SUM(C18:G18) -> 0
A19: Dion | B19: =Données!$E$2 -> 3000 | C19: =$B19*C5 -> 3000 | D19: =$B19*D5 -> 0 | E19: =$B19*E5 -> 0 | F19: =$B19*F5 -> 0 | G19: =$B19*G5 -> 0 | H19: =SUM(C19:G19) -> 3000
A20: Retron | B20: =Données!$E$3 -> 12000 | C20: =$B20*C6 -> 0 | D20: =$B20*D6 -> 0 | E20: =$B20*E6 -> 0 | F20: =$B20*F6 -> 12000 | G20: =$B20*G6 -> 0 | H20: =SUM(C20:G20) -> 12000
A21: Poliard | B21: =Données!$E$4 -> 17000 | C21: =$B21*C7 -> 0 | D21: =$B21*D7 -> 0 | E21: =$B21*E7 -> 17000 | F21: =$B21*F7 -> 0 | G21: =$B21*G7 -> 0 | H21: =SUM(C21:G21) -> 17000
A22: Loudon | B22: =Données!$E$5 -> 18000 | C22: =$B22*C8 -> 0 | D22: =$B22*D8 -> 3600 | E22: =$B22*E8 -> 0 | F22: =$B22*F8 -> 0 | G22: =$B22*G8 -> 14400 | H22: =SUM(C22:G22) -> 18000
A23: Entretien | B23: =Données!$B$12 -> 2400 | C23: =$B23*C9 -> 2400 | D23: =$B23*D9 -> 0 | E23: =$B23*E9 -> 0 | F23: =$B23*F9 -> 0 | G23: =$B23*G9 -> 0 | H23: =SUM(C23:G23) -> 2400
A24: Publicité | B24: =Données!$B$13 -> 5000 | C24: =$B24*C10 -> 0 | D24: =$B24*D10 -> 0 | E24: =$B24*E10 -> 0 | F24: =$B24*F10 -> 0 | G24: =$B24*G10 -> 5000 | H24: =SUM(C24:G24) -> 5000
A25: Transport | B25: =Données!$B$14 -> 1500 | C25: =$B25*C11 -> 0 | D25: =$B25*D11 -> 0 | E25: =$B25*E11 -> 0 | F25: =$B25*F11 -> 0 | G25: =$B25*G11 -> 1500 | H25: =SUM(C25:G25) -> 1500
A26: Total | B26: =SUM(B17:B25) -> 59400 | C26: =SUM(C17:C25) -> 5525 | D26: =SUM(D17:D25) -> 3625 | E26: =SUM(E17:E25) -> 17025 | F26: =SUM(F17:F25) -> 12300 | G26: =SUM(G17:G25) -> 20925
A27: Répartition secondaire
A28: Entretien | B28: =C26 -> 5525 | C28: -1 | E28: 0.25 | F28: 0.5 | G28: 0.25 | H28: =SUM(C28:G28) -> 0
A29: Administration | B29: =D26 -> 3625 | D29: -1 | E29: 0.25 | F29: 0.25 | G29: 0.5 | H29: =SUM(C29:G29) -> 0
A31: Entretien | B31: =B28 -> 5525 | C31: =$B31*C28 -> -5525 | D31: =$B31*D28 -> 0 | E31: =$B31*E28 -> 1381.25 | F31: =$B31*F28 -> 2762.5 | G31: =$B31*G28 -> 1381.25 | H31: =SUM(C31:G31) -> 0
A32: Administration | B32: =B29 -> 3625 | C32: =$B32*C29 -> 0 | D32: =$B32*D29 -> -3625 | E32: =$B32*E29 -> 906.25 | F32: =$B32*F29 -> 906.25 | G32: =$B32*G29 -> 1812.5 | H32: 0
A33: Total | C33: =SUM(C31:C32) -> -5525 | D33: =SUM(D31:D32) -> -3625 | E33: =SUM(E31:E32) -> 2287.5 | F33: =SUM(F31:F32) -> 3668.75 | G33: =SUM(G31:G32) -> 3193.75 | H33: =SUM(H31:H32) -> 0
A34: Total après répartition secondaire | C34: =C26+C33 -> 0 | D34: =D26+D33 -> 0 | E34: =E26+E33 -> 19312.5 | F34: =F26+F33 -> 15968.75 | G34: =G26+G33 -> 24118.75 | H34: =H26+H33 -> 0
A35: Nature de l'unité d'œuvre | E35: 100 € d'achat HT | F35: Heures de MOD | G35: 10 € de vente HT
A36: Nombre d'unité d'œuvre | E36: ='Cout d''achat'!B11/100 -> 1050.2 | F36: =Données!I4 -> 152 | G36: =('Cout de revient'!D12+'Cout de revient'!G12)/10 -> #NUM!
A37: Cout de l'unité d'œuvre | E37: =E34/E36 -> 18.389354 | F37: =F34/F36 -> 105.05757 | G37: =G34/G36 -> #NUM!
B46: Centre Auxiliaire | D46: Centre Principaux
B47: Entretien | C47: Administration | D47: Achat | E47: Assemblage | F47: Commercialisation | G47: Total
A48: Totaux primaire
A49: Entretien
A50: Administration
A51: Totaux secondaires
...

Sheet Cout d'achat
B1: Prix d'achat | C1: Qté acheté | D1: Prix d'achat unitaire | E1: Charges indirectes | F1: Cout d'achat | G1: Cout d'achat unitaire
A2: Roues | B2: 20000 | C2: =2*Données!B22 -> 6400 | D2: =B2/C2 -> 3.125 | E2: =B2/100*'Charges indirectes'!$E$37 -> 3677.8709 | F2: =B2+E2 -> 23677.871 | G2: =F2/C2 -> 3.6996673
A3: Repose Pied | B3: 30000 | C3: =Données!$B$22 -> 3200 | D3: =B3/C3 -> 9.375 | E3: =B3/100*'Charges indirectes'!$E$37 -> 5516.8063 | F3: =B3+E3 -> 35516.806 | G3: =F3/C3 -> 11.099002
A4: Guidons | B4: 30000 | C4: =Données!$B$22 -> 3200 | D4: =B4/C4 -> 9.375 | E4: =B4/100*'Charges indirectes'!$E$37 -> 5516.8063 | F4: =B4+E4 -> 35516.806 | G4: =F4/C4 -> 11.099002
A5: Freins | B5: 10000 | C5: =Données!$B$22 -> 3200 | D5: =B5/C5 -> 3.125 | E5: =B5/100*'Charges indirectes'!$E$37 -> 1838.9354 | F5: =B5+E5 -> 11838.935 | G5: =F5/C5 -> 3.6996673 | I5: Cout d'achat
A6: Auto collant filles | B6: 1500 | C6: =Données!B29 -> 1350 | D6: =B6/C6 -> 1.1111111 | E6: =B6/100*'Charges indirectes'!$E$37 -> 275.84032 | F6: =B6+E6 -> 1775.8403 | G6: =F6/C6 -> 1.3154373 | I6: Prix d'achat + Charges directes liées aux achats + charges indirectes liées aux achats
A7: Auto collant garçons | B7: 2000 | C7: =Données!B30 -> 1850 | D7: =B7/C7 -> 1.0810811 | E7: =B7/100*'Charges indirectes'!$E$37 -> 367.78709 | F7: =B7+E7 -> 2367.7871 | G7: =F7/C7 -> 1.2798849
A8: Emballages garçon | B8: 2035 | C8: =Données!B20 -> 1850 | D8: =B8/C8 -> 1.1 | E8: =B8/100*'Charges indirectes'!$E$37 -> 374.22336 | F8: =B8+E8 -> 2409.2234 | G8: =F8/C8 -> 1.3022829
A9: Emballages fille | B9: 1485 | C9: =Données!B29 -> 1350 | D9: =B9/C9 -> 1.1 | E9: =B9/100*'Charges indirectes'!$E$37 -> 273.08191 | F9: =B9+E9 -> 1758.0819 | G9: =F9/C9 -> 1.3022829
A10: Garde boue | B10: 8000 | C10: =Données!B33 -> 3200 | D10: =B10/C10 -> 2.5 | E10: =B10/100*'Charges indirectes'!$E$37 -> 1471.1484 | F10: =B10+E10 -> 9471.1484 | G10: =F10/C10 -> 2.9597339
A11: Total | B11: =SUM(B2:B10) -> 105020 | E11: =SUM(E2:E10) -> 19312.5 | F11: =SUM(F2:F10) -> 124332.5
B14: Prix d'achat | C14: Qté acheté | D14: Prix d'achat unitaire | E14: Charges indirectes | F14: Cout d'achat | G14: Cout d'achat unitaire
A15: Nom matiere premiere
A17: Total | B17: =SUM(B15:B16) -> 0 | E17: =SUM(E15:E16) -> 0 | F17: =SUM(F15:F16) -> 0

Sheet Stock acheté
A1: Roues
B2: Quantités | C2: Prix unitaire | D2: Montant
A3: Stock initial | B3: 120 | C3: 3.5 | D3: =B3*C3 -> 420
A4: Entrée | B4: ='Cout d''achat'!C2 -> 6400 | C4: ='Cout d''achat'!G2 -> 3.6996673 | D4: =B4*C4 -> 23677.871
A5: Total | B5: =B3+B4 -> 6520 | C5: =D5/B5 -> 3.6959925 | D5: =D3+D4 -> 24097.871 | G5: Les entrées se font au cout d'achat et pas au prix d'achat !!!!
A6: Sortie | B6: =Données!D22*2 -> 6300 | C6: =C5 -> 3.6959925 | D6: =B6*C6 -> 23284.753
A7: Stock final | B7: =B5-B6 -> 220 | C7: =C6 -> 3.6959925 | D7: =B7*C7 -> 813.11834
G8: Les sorties correspondent à ce qui est utilisé par la production
A9: Repose Pieds | G9: Elles se font au cout unitaire moyen pondéré (la méthode de gestion des stock)
B10: Quantités | C10: Prix unitaire | D10: Montant
A11: Stock initial | B11: 60 | C11: 12 | D11: 720
A12: Entrée | B12: 3200 | C12: 11.1 | D12: =C12*B12 -> 35520
A13: Total | B13: 3260 | C13: 11.115585 | D13: 36236.806
A14: Sortie | B14: 3150 | C14: 11.115585 | D14: 35014.092
A15: Stock final | B15: 110 | C15: 11.115585 | D15: 1222.7143
A17: Guidons
B18: Quantités | C18: Prix unitaire | D18: Montant
A19: Stock initial | B19: 60 | C19: 9 | D19: 540
A20: Entrée | B20: 3200 | C20: 11.1 | D20: =C20*B20 -> 35520
A21: Total | B21: 3260 | C21: 11.06037 | D21: =C21*B21 -> 36056.806
A22: Sortie | B22: 3150 | C22: 11.06037 | D22: =C22*B22 -> 34840.166
A23: Stock final | B23: 110 | C23: 11.06037 | D23: =C23*B23 -> 1216.6407
A25: Frein
B26: Quantités | C26: Prix unitaire | D26: Montant
A27: Stock initial | B27: 60 | C27: 4.8 | D27: 288
A28: Entrée | B28: 3200 | C28: 3.7 | D28: =C28*B28 -> 11840
A29: Total | B29: 3260 | C29: 3.7199188 | D29: =C29*B29 -> 12126.935
A30: Sortie | B30: 3150 | C30: 3.7199188 | D30: =C30*B30 -> 11717.744
A31: Stock final | B31: 110 | C31: 3.7199188 | D31: =C31*B31 -> 409.19107
A33: Auto collant filles
B34: Quantités | C34: Prix unitaire | D34: Montant
A35: Stock initial | B35: 20 | C35: 1.05 | D35: 21
A36: Entrée | B36: 1350 | C36: 1.32 | D36: =C36*B36 -> 1782
A37: Total | B37: 1370 | C37: 1.3115623 | D37: =C37*B37 -> 1796.8403
A38: Sortie | B38: 1325 | C38: 1.3115623 | D38: =C38*B38 -> 1737.82
A39: Stock final | B39: 45 | C39: 1.3115623 | D39: =C39*B39 -> 59.020302
A41: Auto collant Garçon
B42: Quantités | C42: Prix unitaire | D42: Montant
A43: Stock initial | B43: 39 | C43: 1.05 | D43: 40.95
A44: Entrée | B44: 1850 | C44: 1.28 | D44: =C44*B44 -> 2368
...

Sheet Cout de production
A1: Cout d'achat des matières utilisées | F1: Garçon | G1: Fille
A2: Roues | B2: ='Stock acheté'!B6 -> 6300 | C2: ='Stock acheté'!C6 -> 3.6959925 | D2: ='Stock acheté'!D6 -> 23284.753 | F2: =Données!$D$20*'Cout de production'!$C2*2 -> 13490.373 | G2: =Données!$D$21*'Cout de production'!$C2*2 -> 9794.38
A3: Repose Pied | B3: ='Stock acheté'!B14 -> 3150 | C3: ='Stock acheté'!C14 -> 11.115585 | D3: ='Stock acheté'!D14 -> 35014.092 | F3: =Données!$D$20*'Cout de production'!$C3 -> 20285.942 | G3: =Données!$D$21*'Cout de production'!$C3 -> 14728.15
A4: Guidons | B4: ='Stock acheté'!B22 -> 3150 | C4: ='Stock acheté'!C22 -> 11.06037 | D4: ='Stock acheté'!D22 -> 34840.166 | F4: =Données!$D$20*'Cout de production'!$C4 -> 20185.175 | G4: =Données!$D$21*'Cout de production'!$C4 -> 14654.99 | H4: Les sorties du stocks
A5: Freins | B5: ='Stock acheté'!B30 -> 3150 | C5: ='Stock acheté'!C30 -> 3.7199188 | D5: ='Stock acheté'!D30 -> 11717.744 | F5: =Données!$D$20*'Cout de production'!$C5 -> 6788.8519 | G5: =Données!$D$21*'Cout de production'!$C5 -> 4928.8925
A6: Auto collant filles | B6: ='Stock acheté'!B38 -> 1325 | C6: ='Stock acheté'!C38 -> 1.3115623 | D6: ='Stock acheté'!D38 -> 1737.82 | G6: =D6 -> 1737.82
A7: Auto collant garçons | B7: ='Stock acheté'!B46 -> 1825 | C7: ='Stock acheté'!C46 -> 1.2751387 | D7: ='Stock acheté'!D46 -> 2327.1282 | F7: =Données!$D$20*'Cout de production'!$C7 -> 2327.1282
A8: Emballages garçon | B8: ='Stock acheté'!B54 -> 1825 | C8: ='Stock acheté'!C54 -> 1.2963794 | D8: ='Stock acheté'!D54 -> 2365.8923 | F8: =Données!$D$20*'Cout de production'!$C8 -> 2365.8923
A9: Emballages fille | B9: ='Stock acheté'!B63 -> 1325 | C9: ='Stock acheté'!C63 -> 1.2981123 | D9: ='Stock acheté'!D63 -> 1719.9987 | G9: =Données!$D$21*'Cout de production'!$C9 -> 1719.9987
A10: Garde boue | B10: ='Stock acheté'!B72 -> 3150 | C10: ='Stock acheté'!C72 -> 2.9835813 | D10: ='Stock acheté'!D72 -> 9398.2812 | F10: =Données!$D$20*'Cout de production'!$C10 -> 5445.036 | G10: =Données!$D$21*'Cout de production'!$C10 -> 3953.2453
A11: Total | F11: =SUM(F2:F10) -> 70888.398 | G11: =SUM(G2:G10) -> 51517.477
A14: Charges directes
A15: Aucune
A17: Charges indirecte
E18: Heures | F18: 70 | G18: 82
E19: Cout unité d'œuvre | F19: ='Charges indirectes'!$F$37 -> 105.05757 | G19: ='Charges indirectes'!$F$37 -> 105.05757
E20: Total | F20: =F18*F19 -> 7354.0296 | G20: =G18*G19 -> 8614.7204
A22: Total | E22: Cout total | F22: =F11+F20 -> 78242.428 | G22: =G11+G20 -> 60132.197
E23: Nombre trotinettes | F23: =Données!D20 -> 1825 | G23: =Données!D21 -> 1325
E24: Cout unitaire | F24: =F22/F23 -> 42.872563 | G24: =G22/G23 -> 45.38279
A27: Cout d'achat des matières utilisées | B27: Nombre acheté | C27: PU dans tableur stock acheté | D27: Total dans stock acheté | F27: Garçon | G27: Fille
A28: Roues | B28: ='Stock acheté'!B32 -> 0 | C28: ='Stock acheté'!C32 -> 0 | D28: ='Stock acheté'!D32 -> 0 | F28: =Données!$D$20*'Cout de production'!$C28*2 -> 0 | G28: =Données!$D$21*'Cout de production'!$C28*2 -> 0 | H28: X2 pour des roues par exemple
A29: Repose Pied | B29: ='Stock acheté'!B40 -> 0 | C29: ='Stock acheté'!C40 -> 0 | D29: ='Stock acheté'!D40 -> 0 | F29: =Données!$D$20*'Cout de production'!$C29 -> 0 | G29: =Données!$D$21*'Cout de production'!$C29 -> 0
A30: Guidons | B30: ='Stock acheté'!B48 -> 0 | C30: ='Stock acheté'!C48 -> 0 | D30: ='Stock acheté'!D48 -> 0 | F30: =Données!$D$20*'Cout de production'!$C30 -> 0 | G30: =Données!$D$21*'Cout de production'!$C30 -> 0
A31: Freins | B31: ='Stock acheté'!B56 -> 0 | C31: ='Stock acheté'!C56 -> 0 | D31: ='Stock acheté'!D56 -> 0 | F31: =Données!$D$20*'Cout de production'!$C31 -> 0 | G31: =Données!$D$21*'Cout de production'!$C31 -> 0
A32: Auto collant filles | B32: ='Stock acheté'!B64 -> 46 | C32: ='Stock acheté'!C64 -> 1.2981123 | D32: ='Stock acheté'!D64 -> 59.713164 | G32: =D32 -> 59.713164
A33: Auto collant garçons | B33: ='Stock acheté'!B72 -> 3150 | C33: ='Stock acheté'!C72 -> 2.9835813 | D33: ='Stock acheté'!D72 -> 9398.2812 | F33: =Données!$D$20*'Cout de production'!$C33 -> 5445.036
A34: Emballages garçon | B34: ='Stock acheté'!B80 -> 0 | C34: ='Stock acheté'!C80 -> 0 | D34: ='Stock acheté'!D80 -> 0 | F34: =Données!$D$20*'Cout de production'!$C34 -> 0
A35: Emballages fille | B35: ='Stock acheté'!B89 -> 0 | C35: ='Stock acheté'!C89 -> 0 | D35: ='Stock acheté'!D89 -> 0 | G35: =Données!$D$21*'Cout de production'!$C35 -> 0
A36: Garde boue | B36: ='Stock acheté'!B98 -> 0 | C36: ='Stock acheté'!C98 -> 0 | D36: ='Stock acheté'!D98 -> 0 | F36: =Données!$D$20*'Cout de production'!$C36 -> 0 | G36: =Données!$D$21*'Cout de production'!$C36 -> 0
A37: Total | F37: =SUM(F28:F36) -> 5445.036 | G37: =SUM(G28:G36) -> 59.713164

Sheet Stock trotinettes
A1: Trotinette garçon
B2: Quantités | C2: Prix unitaire | D2: Montant
A3: Stock initial | B3: 40 | C3: 38 | D3: 1520
A4: Entrée | B4: 1825 | C4: 42.87 | D4: 78242.428 | F4: Entrée : ce qui a été produit valorisé au cout de production
A5: Total | B5: 1865 | C5: 42.77 | D5: 79762.428
A6: Sortie | B6: 1800 | C6: 42.77 | D6: 76982.504 | F6: Sortie : ce qui a été vendu valorisé au cout unitaire moyen pondéré (la méthode d estock)
A7: Stock final | B7: 65 | C7: 42.77 | D7: 2779.9238
A9: Trotinette fille
B10: Quantités | C10: Prix unitaire | D10: Montant
A11: Stock initial | B11: 20 | C11: 45 | D11: 900
A12: Entrée | B12: 1325 | C12: 45.3828 | D12: 60132.197
A13: Total | B13: 1345 | C13: 45.3771 | D13: 61032.197
A14: Sortie | B14: 1300 | C14: 45.3771 | D14: 58990.228
A15: Stock final | B15: 45 | C15: 45.3771 | D15: 2041.9694
A20: Nom Produit
B21: Quantités | C21: Prix unitaire | D21: Montant
A22: Stock initial | D22: =B22*C22 -> 0
A23: Entrée | D23: =B23*C23 -> 0
A24: Total | D24: =B24*C24 -> 0
A25: Sortie | D25: =B25*C25 -> 0
A26: Stock final | D26: =B26*C26 -> 0
A28: Nom Produit
B29: Quantités | C29: Prix unitaire | D29: Montant
A30: Stock initial | D30: =C30*B30 -> 0
A31: Entrée | D31: =C31*B31 -> 0
A32: Total | D32: =B32*C32 -> 0
A33: Sortie | D33: =C33*B33 -> 0
A34: Stock final | D34: =C34*B34 -> 0

Sheet Cout de revient
B1: Garçon | E1: Fille
B2: Qté | C2: PU | D2: Total | E2: Qté | F2: PU | G2: Total
A3: Cout de production des trotinette vendues | B3: ='Stock trotinettes'!B6 -> 1800 | C3: ='Stock trotinettes'!C6 -> 42.77 | D3: =B3*C3 -> 76986 | E3: ='Stock trotinettes'!B14 -> 1300 | F3: ='Stock trotinettes'!C14 -> 45.3771 | G3: =E3*F3 -> 58990.23 | H3: ---> | I3: Les sorties de la fiche de stock
A4: Cout hors production
A5: Livraisons | B5: 1800 | C5: 5 | D5: =B5*C5 -> 9000 | E5: ='Stock trotinettes'!B14 -> 1300 | F5: 5 | G5: =E5*F5 -> 6500
A6: Charges indirectes | B6: =D12/10 -> 9900 | C6: ='Charges indirectes'!G37 -> #NUM! | D6: =B6*C6 -> #NUM! | E6: 7800 | F6: ='Charges indirectes'!G37 -> #NUM! | G6: =E6*F6 -> #NUM! | H6: =D6+G6 -> #NUM!
A9: Cout de revient | B9: =B5 -> 1800 | C9: =D9/B9 -> #NUM! | D9: =SUM(D3:D8) -> #NUM! | E9: =E5 -> 1300 | F9: =G9/E9 -> #NUM! | G9: =SUM(G3:G8) -> #NUM! | H9: --> | I9: Cout de prod des trot vendues+ cout hors prod
A12: CA | B12: =B9 -> 1800 | C12: 55 | D12: =B12*C12 -> 99000 | E12: =E9 -> 1300 | F12: =G9/E9 -> #NUM! | G12: =E12*F12 -> #NUM!
A15: Résutat (CA- cout de revient) | B15: 1800 | C15: =D15/B15 -> #NUM! | D15: =D12-D9 -> #NUM! | E15: 1300 | F15: =G15/E15 -> #NUM! | G15: =G12-G9 -> #NUM! | H15: ---> | I15: CA-Cout de revient
A18: Résultat global | B18: 3100 | C18: =D18/B18 -> #NUM! | D18: =D15+G15 -> #NUM!
B23: Qté | C23: PU | D23: Total | E23: Qté | F23: PU | G23: Total
H24: --->
A30: Cout de revient | H30: -->
A33: CA
A36: Résutat (CA- cout de revient) | H36: --->
A39: Résultat global | C39: =D39/B39 -> #DIV/0!
